<sdf version='1.5'>
  <model name='stickbot_humanoid_32dof'>
    <link name='pelvis'>
      <pose frame=''>0 0 0 0 -0 0</pose>
      <inertial>
        <pose frame=''>0 0 0.05 0 -0 0</pose>
        <mass>2</mass>
        <inertia>
          <ixx>0.008667</ixx>
          <ixy>0</ixy>
          <ixz>0</ixz>
          <iyy>0.008667</iyy>
          <iyz>0</iyz>
          <izz>0.01667</izz>
        </inertia>
      </inertial>
      <collision name='pelvis_collision'>
        <pose frame=''>0 -0 0.05 0 -0 0</pose>
        <geometry>
          <box>
            <size>0.05 0.4 0.1</size>
          </box>
        </geometry>
      </collision>
      <visual name='pelvis_visual'>
        <pose frame=''>0 -0 0.05 0 -0 0</pose>
        <geometry>
          <box>
            <size>0.05 0.4 0.1</size>
          </box>
        </geometry>
      </visual>
    </link>
    <link name='leftHipLink1'>
      <pose frame=''>0 0.2 0 0 -0 0</pose>
      <inertial>
        <pose frame=''>0 0 -0.015 0 -0 0</pose>
        <mass>2</mass>
        <inertia>
          <ixx>0.00015</ixx>
          <ixy>0</ixy>
          <ixz>0</ixz>
          <iyy>0.00015</iyy>
          <iyz>0</iyz>
          <izz>0.000225</izz>
        </inertia>
      </inertial>
      <collision name='leftHipLink1_collision'>
        <pose frame=''>0 0 -0.015 1.507 -0 0</pose>
        <geometry>
          <cylinder>
            <length>0.03</length>
            <radius>0.03</radius>
          </cylinder>
        </geometry>
      </collision>
      <visual name='leftHipLink1_visual'>
        <pose frame=''>0 0 -0.015 0 1.507 0</pose>
        <geometry>
          <cylinder>
            <length>0.03</length>
            <radius>0.03</radius>
          </cylinder>
        </geometry>
      </visual>
    </link>
    <joint name='leftHipJoint1' type='revolute'>
      <child>leftHipLink1</child>
      <parent>pelvis</parent>
      <axis>
        <xyz>0 0 1</xyz>
        <limit>
          <lower>-1e+16</lower>
          <upper>1e+16</upper>
        </limit>
        <dynamics>
          <damping>0.1</damping>
          <friction>0</friction>
          <spring_reference>0</spring_reference>
          <spring_stiffness>0</spring_stiffness>
        </dynamics>
        <use_parent_model_frame>1</use_parent_model_frame>
      </axis>
      <physics>
        <provide_feedback>1</provide_feedback>
        <ode>
          <provide_feedback>1</provide_feedback>
          <limit>
            <cfm>0</cfm>
            <erp>0.2</erp>
          </limit>
        </ode>
      </physics>
    </joint>
    <link name='leftHipExtensorLink'>
      <pose frame=''>0 0.2 -0.03 0 -0 0</pose>
      <inertial>
        <pose frame=''>0 0 -0.015 0 -0 0</pose>
        <mass>2</mass>
        <inertia>
          <ixx>0.00015</ixx>
          <ixy>0</ixy>
          <ixz>0</ixz>
          <iyy>0.00015</iyy>
          <iyz>0</iyz>
          <izz>0.000225</izz>
        </inertia>
      </inertial>
      <collision name='leftHipExtensorLink_collision'>
        <pose frame=''>0 0 -0.015 1.507 -0 0</pose>
        <geometry>
          <cylinder>
            <length>0.03</length>
            <radius>0.03</radius>
          </cylinder>
        </geometry>
      </collision>
      <visual name='leftHipExtensorLink_visual'>
        <pose frame=''>0 0 -0.015 1.507 -0 0</pose>
        <geometry>
          <cylinder>
            <length>0.03</length>
            <radius>0.03</radius>
          </cylinder>
        </geometry>
      </visual>
    </link>
    <joint name='leftHipExtensor' type='revolute'>
      <child>leftHipExtensorLink</child>
      <parent>leftHipLink1</parent>
      <axis>
        <xyz>0 1 0</xyz>
        <limit>
          <lower>-1e+16</lower>
          <upper>1e+16</upper>
        </limit>
        <dynamics>
          <damping>0.1</damping>
          <friction>0</friction>
          <spring_reference>0</spring_reference>
          <spring_stiffness>0</spring_stiffness>
        </dynamics>
        <use_parent_model_frame>1</use_parent_model_frame>
      </axis>
      <physics>
        <provide_feedback>1</provide_feedback>
        <ode>
          <provide_feedback>1</provide_feedback>
          <limit>
            <cfm>0</cfm>
            <erp>0.2</erp>
          </limit>
        </ode>
      </physics>
    </joint>
    <link name='leftUpperLeg'>
      <pose frame=''>0 0.2 -0.06 0 -0 0</pose>
      <inertial>
        <pose frame=''>-0 0 -0.15 0 -0 0</pose>
        <mass>2</mass>
        <inertia>
          <ixx>0.01545</ixx>
          <ixy>0</ixy>
          <ixz>0</ixz>
          <iyy>0.01545</iyy>
          <iyz>0</iyz>
          <izz>0.0009</izz>
        </inertia>
      </inertial>
      <collision name='leftUpperLeg_collision'>
        <pose frame=''>0 0 -0.3 0 -0 0</pose>
        <geometry>
          <cylinder>
            <length>0.3</length>
            <radius>0.03</radius>
          </cylinder>
        </geometry>
      </collision>
      <visual name='leftUpperLeg_visual'>
        <pose frame=''>0 0 -0.15 0 -0 0</pose>
        <geometry>
          <cylinder>
            <length>0.3</length>
            <radius>0.03</radius>
          </cylinder>
        </geometry>
      </visual>
    </link>
    <joint name='leftHipAductor' type='revolute'>
      <child>leftUpperLeg</child>
      <parent>leftHipExtensorLink</parent>
      <axis>
        <xyz>1 0 0</xyz>
        <limit>
          <lower>-1e+16</lower>
          <upper>1e+16</upper>
        </limit>
        <dynamics>
          <damping>0.1</damping>
          <friction>0</friction>
          <spring_reference>0</spring_reference>
          <spring_stiffness>0</spring_stiffness>
        </dynamics>
        <use_parent_model_frame>1</use_parent_model_frame>
      </axis>
      <physics>
        <provide_feedback>1</provide_feedback>
        <ode>
          <provide_feedback>1</provide_feedback>
          <limit>
            <cfm>0</cfm>
            <erp>0.2</erp>
          </limit>
        </ode>
      </physics>
    </joint>
    <link name='leftLowerLeg'>
      <pose frame=''>0 0.2 -0.36 0 -0 0</pose>
      <inertial>
        <pose frame=''>-0 0 -0.15 0 -0 0</pose>
        <mass>2</mass>
        <inertia>
          <ixx>0.01545</ixx>
          <ixy>0</ixy>
          <ixz>0</ixz>
          <iyy>0.01545</iyy>
          <iyz>0</iyz>
          <izz>0.0009</izz>
        </inertia>
      </inertial>
      <collision name='leftLowerLeg_collision'>
        <pose frame=''>0 0 -0.15 0 -0 0</pose>
        <geometry>
          <cylinder>
            <length>0.3</length>
            <radius>0.03</radius>
          </cylinder>
        </geometry>
      </collision>
      <visual name='leftLowerLeg_visual'>
        <pose frame=''>0 0 -0.15 0 -0 0</pose>
        <geometry>
          <cylinder>
            <length>0.3</length>
            <radius>0.03</radius>
          </cylinder>
        </geometry>
      </visual>
    </link>
    <joint name='leftKnee' type='revolute'>
      <child>leftLowerLeg</child>
      <parent>leftUpperLeg</parent>
      <axis>
        <xyz>0 1 0</xyz>
        <limit>
          <lower>-1e+16</lower>
          <upper>1e+16</upper>
        </limit>
        <dynamics>
          <damping>0.1</damping>
          <friction>0</friction>
          <spring_reference>0</spring_reference>
          <spring_stiffness>0</spring_stiffness>
        </dynamics>
        <use_parent_model_frame>1</use_parent_model_frame>
      </axis>
      <physics>
        <provide_feedback>1</provide_feedback>
        <ode>
          <provide_feedback>1</provide_feedback>
          <limit>
            <cfm>0</cfm>
            <erp>0.2</erp>
          </limit>
        </ode>
      </physics>
    </joint>
    <link name='leftAnkleLink'>
      <pose frame=''>0 0.2 -0.66 0 -0 0</pose>
      <inertial>
        <pose frame=''>0 0 -0.015 0 -0 0</pose>
        <mass>3</mass>
        <inertia>
          <ixx>0.00015</ixx>
          <ixy>0</ixy>
          <ixz>0</ixz>
          <iyy>0.00015</iyy>
          <iyz>0</iyz>
          <izz>0.000225</izz>
        </inertia>
      </inertial>
      <collision name='leftAnkleLink_collision'>
        <pose frame=''>0 0 -0.015 0 -0 0</pose>
        <geometry>
          <cylinder>
            <length>0.03</length>
            <radius>0.03</radius>
          </cylinder>
        </geometry>
      </collision>
      <visual name='leftAnkleLink_visual'>
        <pose frame=''>0 0 -0.015 1.507 -0 0</pose>
        <geometry>
          <cylinder>
            <length>0.03</length>
            <radius>0.03</radius>
          </cylinder>
        </geometry>
      </visual>
    </link>
    <joint name='leftAnklePitch' type='revolute'>
      <child>leftAnkleLink</child>
      <parent>leftLowerLeg</parent>
      <axis>
        <xyz>0 1 0</xyz>
        <limit>
          <lower>-1e+16</lower>
          <upper>1e+16</upper>
        </limit>
        <dynamics>
          <damping>0.1</damping>
          <friction>0</friction>
          <spring_reference>0</spring_reference>
          <spring_stiffness>0</spring_stiffness>
        </dynamics>
        <use_parent_model_frame>1</use_parent_model_frame>
      </axis>
      <physics>
        <provide_feedback>1</provide_feedback>
        <ode>
          <provide_feedback>1</provide_feedback>
          <limit>
            <cfm>0</cfm>
            <erp>0.2</erp>
          </limit>
        </ode>
      </physics>
    </joint>
    <link name='leftFoot'>
      <pose frame=''>0.025 0.2 -0.69 0 -0 0</pose>
      <inertial>
        <pose frame=''>0.03 0 -0.01 0 -0 0</pose>
        <mass>10</mass>
        <inertia>
          <ixx>0.008667</ixx>
          <ixy>0</ixy>
          <ixz>0</ixz>
          <iyy>0.008667</iyy>
          <iyz>0</iyz>
          <izz>0.01667</izz>
        </inertia>
      </inertial>
      <collision name='leftFoot_collision'>
        <pose frame=''>0 0 -0.02 0 -0 0</pose>
        <geometry>
          <box>
            <size>0.5 0.3 0.04</size>
          </box>
        </geometry>
      </collision>
      <visual name='leftFoot_visual'>
        <pose frame=''>0 0 -0.02 0 -0 0</pose>
        <geometry>
          <box>
            <size>0.5 0.3 0.04</size>
          </box>
        </geometry>
      </visual>
    </link>
    <joint name='leftAnkleRoll' type='revolute'>
      <child>leftFoot</child>
      <parent>leftAnkleLink</parent>
      <axis>
        <xyz>1 0 0</xyz>
        <limit>
          <lower>-1e+16</lower>
          <upper>1e+16</upper>
        </limit>
        <dynamics>
          <damping>0.1</damping>
          <friction>0</friction>
          <spring_reference>0</spring_reference>
          <spring_stiffness>0</spring_stiffness>
        </dynamics>
        <use_parent_model_frame>1</use_parent_model_frame>
      </axis>
      <physics>
        <provide_feedback>1</provide_feedback>
        <ode>
          <provide_feedback>1</provide_feedback>
          <limit>
            <cfm>0</cfm>
            <erp>0.2</erp>
          </limit>
        </ode>
      </physics>
    </joint>
    <link name='rightHipLink1'>
      <pose frame=''>0 -0.2 0 0 -0 0</pose>
      <inertial>
        <pose frame=''>0 0 -0.015 0 -0 0</pose>
        <mass>2</mass>
        <inertia>
          <ixx>0.00015</ixx>
          <ixy>0</ixy>
          <ixz>0</ixz>
          <iyy>0.00015</iyy>
          <iyz>0</iyz>
          <izz>0.000225</izz>
        </inertia>
      </inertial>
      <collision name='rightHipLink1_collision'>
        <pose frame=''>0 0 -0.015 1.507 -0 0</pose>
        <geometry>
          <cylinder>
            <length>0.03</length>
            <radius>0.03</radius>
          </cylinder>
        </geometry>
      </collision>
      <visual name='rightHipLink1_visual'>
        <pose frame=''>0 0 -0.015 0 1.507 0</pose>
        <geometry>
          <cylinder>
            <length>0.03</length>
            <radius>0.03</radius>
          </cylinder>
        </geometry>
      </visual>
    </link>
    <joint name='rightHipJoint1' type='revolute'>
      <child>rightHipLink1</child>
      <parent>pelvis</parent>
      <axis>
        <xyz>0 0 1</xyz>
        <limit>
          <lower>-1e+16</lower>
          <upper>1e+16</upper>
        </limit>
        <dynamics>
          <damping>0.1</damping>
          <friction>0</friction>
          <spring_reference>0</spring_reference>
          <spring_stiffness>0</spring_stiffness>
        </dynamics>
        <use_parent_model_frame>1</use_parent_model_frame>
      </axis>
      <physics>
        <provide_feedback>1</provide_feedback>
        <ode>
          <provide_feedback>1</provide_feedback>
          <limit>
            <cfm>0</cfm>
            <erp>0.2</erp>
          </limit>
        </ode>
      </physics>
    </joint>
    <link name='rightHipExtensorLink'>
      <pose frame=''>0 -0.2 -0.03 0 -0 0</pose>
      <inertial>
        <pose frame=''>0 0 -0.015 0 -0 0</pose>
        <mass>2</mass>
        <inertia>
          <ixx>0.00015</ixx>
          <ixy>0</ixy>
          <ixz>0</ixz>
          <iyy>0.00015</iyy>
          <iyz>0</iyz>
          <izz>0.000225</izz>
        </inertia>
      </inertial>
      <collision name='rightHipExtensorLink_collision'>
        <pose frame=''>0 0 -0.015 1.507 -0 0</pose>
        <geometry>
          <cylinder>
            <length>0.03</length>
            <radius>0.03</radius>
          </cylinder>
        </geometry>
      </collision>
      <visual name='rightHipExtensorLink_visual'>
        <pose frame=''>0 0 -0.015 1.507 -0 0</pose>
        <geometry>
          <cylinder>
            <length>0.03</length>
            <radius>0.03</radius>
          </cylinder>
        </geometry>
      </visual>
    </link>
    <joint name='rightHipExtensor' type='revolute'>
      <child>rightHipExtensorLink</child>
      <parent>rightHipLink1</parent>
      <axis>
        <xyz>0 1 0</xyz>
        <limit>
          <lower>-1e+16</lower>
          <upper>1e+16</upper>
        </limit>
        <dynamics>
          <damping>0.1</damping>
          <friction>0</friction>
          <spring_reference>0</spring_reference>
          <spring_stiffness>0</spring_stiffness>
        </dynamics>
        <use_parent_model_frame>1</use_parent_model_frame>
      </axis>
      <physics>
        <provide_feedback>1</provide_feedback>
        <ode>
          <provide_feedback>1</provide_feedback>
          <limit>
            <cfm>0</cfm>
            <erp>0.2</erp>
          </limit>
        </ode>
      </physics>
    </joint>
    <link name='rightUpperLeg'>
      <pose frame=''>0 -0.2 -0.06 0 -0 0</pose>
      <inertial>
        <pose frame=''>-0 0 -0.15 0 -0 0</pose>
        <mass>2</mass>
        <inertia>
          <ixx>0.01545</ixx>
          <ixy>0</ixy>
          <ixz>0</ixz>
          <iyy>0.01545</iyy>
          <iyz>0</iyz>
          <izz>0.0009</izz>
        </inertia>
      </inertial>
      <collision name='rightUpperLeg_collision'>
        <pose frame=''>0 0 -0.3 0 -0 0</pose>
        <geometry>
          <cylinder>
            <length>0.3</length>
            <radius>0.03</radius>
          </cylinder>
        </geometry>
      </collision>
      <visual name='rightUpperLeg_visual'>
        <pose frame=''>0 0 -0.15 0 -0 0</pose>
        <geometry>
          <cylinder>
            <length>0.3</length>
            <radius>0.03</radius>
          </cylinder>
        </geometry>
      </visual>
    </link>
    <joint name='rightHipAductor' type='revolute'>
      <child>rightUpperLeg</child>
      <parent>rightHipExtensorLink</parent>
      <axis>
        <xyz>1 0 0</xyz>
        <limit>
          <lower>-1e+16</lower>
          <upper>1e+16</upper>
        </limit>
        <dynamics>
          <damping>0.1</damping>
          <friction>0</friction>
          <spring_reference>0</spring_reference>
          <spring_stiffness>0</spring_stiffness>
        </dynamics>
        <use_parent_model_frame>1</use_parent_model_frame>
      </axis>
      <physics>
        <provide_feedback>1</provide_feedback>
        <ode>
          <provide_feedback>1</provide_feedback>
          <limit>
            <cfm>0</cfm>
            <erp>0.2</erp>
          </limit>
        </ode>
      </physics>
    </joint>
    <link name='rightLowerLeg'>
      <pose frame=''>0 -0.2 -0.36 0 -0 0</pose>
      <inertial>
        <pose frame=''>-0 0 -0.15 0 -0 0</pose>
        <mass>2</mass>
        <inertia>
          <ixx>0.01545</ixx>
          <ixy>0</ixy>
          <ixz>0</ixz>
          <iyy>0.01545</iyy>
          <iyz>0</iyz>
          <izz>0.0009</izz>
        </inertia>
      </inertial>
      <collision name='rightLowerLeg_collision'>
        <pose frame=''>0 0 -0.15 0 -0 0</pose>
        <geometry>
          <cylinder>
            <length>0.3</length>
            <radius>0.03</radius>
          </cylinder>
        </geometry>
      </collision>
      <visual name='rightLowerLeg_visual'>
        <pose frame=''>0 0 -0.15 0 -0 0</pose>
        <geometry>
          <cylinder>
            <length>0.3</length>
            <radius>0.03</radius>
          </cylinder>
        </geometry>
      </visual>
    </link>
    <joint name='rightKnee' type='revolute'>
      <child>rightLowerLeg</child>
      <parent>rightUpperLeg</parent>
      <axis>
        <xyz>0 1 0</xyz>
        <limit>
          <lower>-1e+16</lower>
          <upper>1e+16</upper>
        </limit>
        <dynamics>
          <damping>0.1</damping>
          <friction>0</friction>
          <spring_reference>0</spring_reference>
          <spring_stiffness>0</spring_stiffness>
        </dynamics>
        <use_parent_model_frame>1</use_parent_model_frame>
      </axis>
      <physics>
        <provide_feedback>1</provide_feedback>
        <ode>
          <provide_feedback>1</provide_feedback>
          <limit>
            <cfm>0</cfm>
            <erp>0.2</erp>
          </limit>
        </ode>
      </physics>
    </joint>
    <link name='rightAnkleLink'>
      <pose frame=''>0 -0.2 -0.66 0 -0 0</pose>
      <inertial>
        <pose frame=''>0 0 -0.015 0 -0 0</pose>
        <mass>3</mass>
        <inertia>
          <ixx>0.00015</ixx>
          <ixy>0</ixy>
          <ixz>0</ixz>
          <iyy>0.00015</iyy>
          <iyz>0</iyz>
          <izz>0.000225</izz>
        </inertia>
      </inertial>
      <collision name='rightAnkleLink_collision'>
        <pose frame=''>0 0 -0.015 1.507 -0 0</pose>
        <geometry>
          <cylinder>
            <length>0.03</length>
            <radius>0.03</radius>
          </cylinder>
        </geometry>
      </collision>
      <visual name='rightAnkleLink_visual'>
        <pose frame=''>0 0 -0.015 1.507 -0 0</pose>
        <geometry>
          <cylinder>
            <length>0.03</length>
            <radius>0.03</radius>
          </cylinder>
        </geometry>
      </visual>
    </link>
    <joint name='rightAnklePitch' type='revolute'>
      <child>rightAnkleLink</child>
      <parent>rightLowerLeg</parent>
      <axis>
        <xyz>0 1 0</xyz>
        <limit>
          <lower>-1e+16</lower>
          <upper>1e+16</upper>
        </limit>
        <dynamics>
          <damping>0.1</damping>
          <friction>0</friction>
          <spring_reference>0</spring_reference>
          <spring_stiffness>0</spring_stiffness>
        </dynamics>
        <use_parent_model_frame>1</use_parent_model_frame>
      </axis>
      <physics>
        <provide_feedback>1</provide_feedback>
        <ode>
          <provide_feedback>1</provide_feedback>
          <limit>
            <cfm>0</cfm>
            <erp>0.2</erp>
          </limit>
        </ode>
      </physics>
    </joint>
    <link name='rightFoot'>
      <pose frame=''>0.025 -0.2 -0.69 0 -0 0</pose>
      <inertial>
        <pose frame=''>0.03 0 -0.02 0 -0 0</pose>
        <mass>10</mass>
        <inertia>
          <ixx>0.008667</ixx>
          <ixy>0</ixy>
          <ixz>0</ixz>
          <iyy>0.008667</iyy>
          <iyz>0</iyz>
          <izz>0.01667</izz>
        </inertia>
      </inertial>
      <collision name='rightFoot_collision'>
        <pose frame=''>0 0 -0.02 0 -0 0</pose>
        <geometry>
          <box>
            <size>0.5 0.3 0.04</size>
          </box>
        </geometry>
      </collision>
      <visual name='rightFoot_visual'>
        <pose frame=''>0 0 -0.02 0 -0 0</pose>
        <geometry>
          <box>
            <size>0.5 0.3 0.04</size>
          </box>
        </geometry>
      </visual>
    </link>
    <joint name='rightAnkleRoll' type='revolute'>
      <child>rightFoot</child>
      <parent>rightAnkleLink</parent>
      <axis>
        <xyz>1 0 0</xyz>
        <limit>
          <lower>-1e+16</lower>
          <upper>1e+16</upper>
        </limit>
        <dynamics>
          <damping>0.1</damping>
          <friction>0</friction>
          <spring_reference>0</spring_reference>
          <spring_stiffness>0</spring_stiffness>
        </dynamics>
        <use_parent_model_frame>1</use_parent_model_frame>
      </axis>
      <physics>
        <provide_feedback>1</provide_feedback>
        <ode>
          <provide_feedback>1</provide_feedback>
          <limit>
            <cfm>0</cfm>
            <erp>0.2</erp>
          </limit>
        </ode>
      </physics>
    </joint>
    <link name='abdomen'>
      <pose frame=''>0 0 0.1 0 -0 0</pose>
      <inertial>
        <pose frame=''>0 0 0.125 0 -0 0</pose>
        <mass>1</mass>
        <inertia>
          <ixx>0.028125</ixx>
          <ixy>0</ixy>
          <ixz>0</ixz>
          <iyy>0.045</iyy>
          <iyz>0</iyz>
          <izz>0.028125</izz>
        </inertia>
      </inertial>
      <collision name='abdomen_collision'>
        <pose frame=''>0 0 0.015 0 -0 0</pose>
        <geometry>
          <cylinder>
            <length>0.03</length>
            <radius>0.1</radius>
          </cylinder>
        </geometry>
      </collision>
      <visual name='abdomen_visual'>
        <pose frame=''>0 0 0.015 0 -0 0</pose>
        <geometry>
          <cylinder>
            <length>0.03</length>
            <radius>0.1</radius>
          </cylinder>
        </geometry>
      </visual>
    </link>
    <joint name='waist_rotator' type='revolute'>
      <child>abdomen</child>
      <parent>pelvis</parent>
      <axis>
        <xyz>0 0 1</xyz>
        <limit>
          <lower>-1e+16</lower>
          <upper>1e+16</upper>
        </limit>
        <dynamics>
          <damping>0.1</damping>
          <friction>0</friction>
          <spring_reference>0</spring_reference>
          <spring_stiffness>0</spring_stiffness>
        </dynamics>
        <use_parent_model_frame>1</use_parent_model_frame>
      </axis>
      <physics>
        <provide_feedback>1</provide_feedback>
        <ode>
          <provide_feedback>1</provide_feedback>
          <limit>
            <cfm>0</cfm>
            <erp>0.2</erp>
          </limit>
        </ode>
      </physics>
    </joint>
    <link name='torso'>
      <pose frame=''>0 0 0.13 0 -0 0</pose>
      <inertial>
        <pose frame=''>0 0 0.125 0 -0 0</pose>
        <mass>2</mass>
        <inertia>
          <ixx>0.028125</ixx>
          <ixy>0</ixy>
          <ixz>0</ixz>
          <iyy>0.045</iyy>
          <iyz>0</iyz>
          <izz>0.028125</izz>
        </inertia>
      </inertial>
      <collision name='torso_collision'>
        <pose frame=''>0 0 0.125 0 -0 0</pose>
        <geometry>
          <box>
            <size>0.12 0.25 0.25</size>
          </box>
        </geometry>
      </collision>
      <visual name='torso_visual'>
        <pose frame=''>0 0 0.125 0 -0 0</pose>
        <geometry>
          <box>
            <size>0.12 0.25 0.25</size>
          </box>
        </geometry>
      </visual>
    </link>
    <joint name='torso_extensor' type='revolute'>
      <child>torso</child>
      <parent>abdomen</parent>
      <axis>
        <xyz>0 1 0</xyz>
        <limit>
          <lower>-1e+16</lower>
          <upper>1e+16</upper>
        </limit>
        <dynamics>
          <damping>0.1</damping>
          <friction>0</friction>
          <spring_reference>0</spring_reference>
          <spring_stiffness>0</spring_stiffness>
        </dynamics>
        <use_parent_model_frame>1</use_parent_model_frame>
      </axis>
      <physics>
        <provide_feedback>1</provide_feedback>
        <ode>
          <provide_feedback>1</provide_feedback>
          <limit>
            <cfm>0</cfm>
            <erp>0.2</erp>
          </limit>
        </ode>
      </physics>
    </joint>
    <link name='chest'>
      <pose frame=''>0 0 0.38 0 -0 0</pose>
      <inertial>
        <pose frame=''>0 0 0.125 0 -0 0</pose>
        <mass>2</mass>
        <inertia>
          <ixx>0.028125</ixx>
          <ixy>0</ixy>
          <ixz>0</ixz>
          <iyy>0.045</iyy>
          <iyz>0</iyz>
          <izz>0.028125</izz>
        </inertia>
      </inertial>
      <collision name='chest_collision'>
        <pose frame=''>0 0 0.125 0 -0 0</pose>
        <geometry>
          <box>
            <size>0.12 0.25 0.25</size>
          </box>
        </geometry>
      </collision>
      <visual name='chest_visual'>
        <pose frame=''>0 0 0.125 0 -0 0</pose>
        <geometry>
          <box>
            <size>0.12 0.25 0.25</size>
          </box>
        </geometry>
      </visual>
    </link>
    <joint name='chest_extensor' type='revolute'>
      <child>chest</child>
      <parent>torso</parent>
      <axis>
        <xyz>0 1 0</xyz>
        <limit>
          <lower>-1e+16</lower>
          <upper>1e+16</upper>
        </limit>
        <dynamics>
          <damping>0.1</damping>
          <friction>0</friction>
          <spring_reference>0</spring_reference>
          <spring_stiffness>0</spring_stiffness>
        </dynamics>
        <use_parent_model_frame>1</use_parent_model_frame>
      </axis>
      <physics>
        <provide_feedback>1</provide_feedback>
        <ode>
          <provide_feedback>1</provide_feedback>
          <limit>
            <cfm>0</cfm>
            <erp>0.2</erp>
          </limit>
        </ode>
      </physics>
    </joint>
    <link name='left_shoulder_extensor'>
      <pose frame=''>0 0.125 0.6 0 -0 0</pose>
      <inertial>
        <pose frame=''>0 0.01 0 0 -0 0</pose>
        <mass>1</mass>
        <inertia>
          <ixx>0.028125</ixx>
          <ixy>0</ixy>
          <ixz>0</ixz>
          <iyy>0.045</iyy>
          <iyz>0</iyz>
          <izz>0.028125</izz>
        </inertia>
      </inertial>
      <collision name='left_shoulder_extensor_collision'>
        <pose frame=''>0 0.01 0 1.57 -0 0</pose>
        <geometry>
          <cylinder>
            <length>0.02</length>
            <radius>0.06</radius>
          </cylinder>
        </geometry>
        <surface>
          <contact>
            <ode/>
          </contact>
          <friction>
            <ode/>
          </friction>
        </surface>
      </collision>
      <visual name='left_shoulder_extensor_visual'>
        <pose frame=''>0 0.01 0 1.57 -0 0</pose>
        <geometry>
          <cylinder>
            <length>0.02</length>
            <radius>0.06</radius>
          </cylinder>
        </geometry>
        <material>
          <script>
            <uri>__default__</uri>
            <name>__default__</name>
          </script>
        </material>
      </visual>
      <gravity>1</gravity>
      <velocity_decay/>
      <self_collide>0</self_collide>
    </link>
    <joint name='left_shoulder_extensor' type='revolute'>
      <child>left_shoulder_extensor</child>
      <parent>chest</parent>
      <axis>
        <xyz>0 1 0</xyz>
        <limit>
          <lower>-1e+16</lower>
          <upper>1e+16</upper>
        </limit>
        <dynamics>
          <damping>0.1</damping>
          <friction>0</friction>
          <spring_reference>0</spring_reference>
          <spring_stiffness>0</spring_stiffness>
        </dynamics>
        <use_parent_model_frame>1</use_parent_model_frame>
      </axis>
      <physics>
        <provide_feedback>1</provide_feedback>
        <ode>
          <provide_feedback>1</provide_feedback>
          <limit>
            <cfm>0</cfm>
            <erp>0.2</erp>
          </limit>
        </ode>
      </physics>
    </joint>
    <link name='left_shoulder_adductor'>
      <pose frame=''>0 0.165 0.6 0 -0 0</pose>
      <inertial>
        <pose frame=''>0 0.02 0 0 -0 0</pose>
        <mass>1</mass>
        <inertia>
          <ixx>0.028125</ixx>
          <ixy>0</ixy>
          <ixz>0</ixz>
          <iyy>0.045</iyy>
          <iyz>0</iyz>
          <izz>0.028125</izz>
        </inertia>
      </inertial>
      <collision name='left_shoulder_adductor_collision'>
        <pose frame=''>0 0.02 0 0 1.57 0</pose>
        <geometry>
          <cylinder>
            <length>0.1</length>
            <radius>0.04</radius>
          </cylinder>
        </geometry>
        <surface>
          <contact>
            <ode/>
          </contact>
          <friction>
            <ode/>
          </friction>
        </surface>
      </collision>
      <visual name='left_shoulder_adductor_visual'>
        <pose frame=''>0 0.02 0 0 1.57 0</pose>
        <geometry>
          <cylinder>
            <length>0.1</length>
            <radius>0.04</radius>
          </cylinder>
        </geometry>
        <material>
          <script>
            <uri>__default__</uri>
            <name>__default__</name>
          </script>
        </material>
      </visual>
      <gravity>1</gravity>
      <velocity_decay/>
      <self_collide>0</self_collide>
    </link>
    <joint name='left_shoulder_adductor' type='revolute'>
      <child>left_shoulder_adductor</child>
      <parent>left_shoulder_extensor</parent>
      <axis>
        <xyz>1 0 0</xyz>
        <limit>
          <lower>-1e+16</lower>
          <upper>1e+16</upper>
        </limit>
        <dynamics>
          <damping>0.1</damping>
          <friction>0</friction>
          <spring_reference>0</spring_reference>
          <spring_stiffness>0</spring_stiffness>
        </dynamics>
        <use_parent_model_frame>1</use_parent_model_frame>
      </axis>
      <physics>
        <provide_feedback>1</provide_feedback>
        <ode>
          <provide_feedback>1</provide_feedback>
          <limit>
            <cfm>0</cfm>
            <erp>0.2</erp>
          </limit>
        </ode>
      </physics>
    </joint>
    <link name='left_shoulder_rotator'>
      <pose frame=''>0 0.185 0.58 0 -0 0</pose>
      <inertial>
        <pose frame=''>0 0 -0.1 0 -0 0</pose>
        <mass>2</mass>
        <inertia>
          <ixx>0.028125</ixx>
          <ixy>0</ixy>
          <ixz>0</ixz>
          <iyy>0.045</iyy>
          <iyz>0</iyz>
          <izz>0.028125</izz>
        </inertia>
      </inertial>
      <collision name='left_shoulder_rotator_collision'>
        <pose frame=''>0 0 -0.1 0 -0 0</pose>
        <geometry>
          <cylinder>
            <length>0.2</length>
            <radius>0.03</radius>
          </cylinder>
        </geometry>
        <surface>
          <contact>
            <ode/>
          </contact>
          <friction>
            <ode/>
          </friction>
        </surface>
      </collision>
      <visual name='left_shoulder_rotator_visual'>
        <pose frame=''>0 0 -0.1 0 -0 0</pose>
        <geometry>
          <cylinder>
            <length>0.2</length>
            <radius>0.03</radius>
          </cylinder>
        </geometry>
        <material>
          <script>
            <uri>__default__</uri>
            <name>__default__</name>
          </script>
        </material>
      </visual>
      <gravity>1</gravity>
      <velocity_decay/>
      <self_collide>0</self_collide>
    </link>
    <joint name='left_shoulder_rotator' type='revolute'>
      <child>left_shoulder_rotator</child>
      <parent>left_shoulder_adductor</parent>
      <axis>
        <xyz>0 0 1</xyz>
        <limit>
          <lower>-1e+16</lower>
          <upper>1e+16</upper>
        </limit>
        <dynamics>
          <damping>0.1</damping>
          <friction>0</friction>
          <spring_reference>0</spring_reference>
          <spring_stiffness>0</spring_stiffness>
        </dynamics>
        <use_parent_model_frame>1</use_parent_model_frame>
      </axis>
      <physics>
        <provide_feedback>1</provide_feedback>
        <ode>
          <provide_feedback>1</provide_feedback>
          <limit>
            <cfm>0</cfm>
            <erp>0.2</erp>
          </limit>
        </ode>
      </physics>
    </joint>
    <link name='left_elbow_extensor'>
      <pose frame=''>0 0.185 0.38 0 -0 0</pose>
      <inertial>
        <pose frame=''>0 0 -0.1 0 -0 0</pose>
        <mass>2</mass>
        <inertia>
          <ixx>0.028125</ixx>
          <ixy>0</ixy>
          <ixz>0</ixz>
          <iyy>0.045</iyy>
          <iyz>0</iyz>
          <izz>0.028125</izz>
        </inertia>
      </inertial>
      <collision name='left_elbow_extensor_collision'>
        <pose frame=''>0 0 -0.1 0 -0 0</pose>
        <geometry>
          <cylinder>
            <length>0.2</length>
            <radius>0.03</radius>
          </cylinder>
        </geometry>
        <surface>
          <contact>
            <ode/>
          </contact>
          <friction>
            <ode/>
          </friction>
        </surface>
      </collision>
      <visual name='left_elbow_extensor_visual'>
        <pose frame=''>0 0 -0.1 0 -0 0</pose>
        <geometry>
          <cylinder>
            <length>0.2</length>
            <radius>0.03</radius>
          </cylinder>
        </geometry>
        <material>
          <script>
            <uri>__default__</uri>
            <name>__default__</name>
          </script>
        </material>
      </visual>
      <gravity>1</gravity>
      <velocity_decay/>
      <self_collide>0</self_collide>
    </link>
    <joint name='left_elbow_extensor' type='revolute'>
      <child>left_elbow_extensor</child>
      <parent>left_shoulder_rotator</parent>
      <axis>
        <xyz>0 1 0</xyz>
        <limit>
          <lower>-1e+16</lower>
          <upper>1e+16</upper>
        </limit>
        <dynamics>
          <damping>0.1</damping>
          <friction>0</friction>
          <spring_reference>0</spring_reference>
          <spring_stiffness>0</spring_stiffness>
        </dynamics>
        <use_parent_model_frame>1</use_parent_model_frame>
      </axis>
      <physics>
        <provide_feedback>1</provide_feedback>
        <ode>
          <provide_feedback>1</provide_feedback>
          <limit>
            <cfm>0</cfm>
            <erp>0.2</erp>
          </limit>
        </ode>
      </physics>
    </joint>
    <link name='left_wrist_rotator'>
      <pose frame=''>0 0.185 0.18 0 -0 0</pose>
      <inertial>
        <pose frame=''>0 0 -0.02 0 -0 0</pose>
        <mass>2</mass>
        <inertia>
          <ixx>0.028125</ixx>
          <ixy>0</ixy>
          <ixz>0</ixz>
          <iyy>0.045</iyy>
          <iyz>0</iyz>
          <izz>0.028125</izz>
        </inertia>
      </inertial>
      <collision name='left_wrist_rotator_collision'>
        <pose frame=''>0 0 -0.02 0 -0 0</pose>
        <geometry>
          <cylinder>
            <length>0.04</length>
            <radius>0.03</radius>
          </cylinder>
        </geometry>
        <surface>
          <contact>
            <ode/>
          </contact>
          <friction>
            <ode/>
          </friction>
        </surface>
      </collision>
      <visual name='left_wrist_rotator_visual'>
        <pose frame=''>0 0 -0.02 0 -0 0</pose>
        <geometry>
          <cylinder>
            <length>0.04</length>
            <radius>0.03</radius>
          </cylinder>
        </geometry>
        <material>
          <script>
            <uri>__default__</uri>
            <name>__default__</name>
          </script>
        </material>
      </visual>
      <gravity>1</gravity>
      <velocity_decay/>
      <self_collide>0</self_collide>
    </link>
    <joint name='left_wrist_rotator' type='revolute'>
      <child>left_wrist_rotator</child>
      <parent>left_elbow_extensor</parent>
      <axis>
        <xyz>0 0 1</xyz>
        <limit>
          <lower>-1e+16</lower>
          <upper>1e+16</upper>
        </limit>
        <dynamics>
          <damping>0.1</damping>
          <friction>0</friction>
          <spring_reference>0</spring_reference>
          <spring_stiffness>0</spring_stiffness>
        </dynamics>
        <use_parent_model_frame>1</use_parent_model_frame>
      </axis>
      <physics>
        <provide_feedback>1</provide_feedback>
        <ode>
          <provide_feedback>1</provide_feedback>
          <limit>
            <cfm>0</cfm>
            <erp>0.2</erp>
          </limit>
        </ode>
      </physics>
    </joint>
    <link name='left_wrist_extensor'>
      <pose frame=''>0 0.185 0.16 0 -0 0</pose>
      <inertial>
        <pose frame=''>0 0 -0.02 0 -0 0</pose>
        <mass>1</mass>
        <inertia>
          <ixx>0.028125</ixx>
          <ixy>0</ixy>
          <ixz>0</ixz>
          <iyy>0.045</iyy>
          <iyz>0</iyz>
          <izz>0.028125</izz>
        </inertia>
      </inertial>
      <collision name='left_wrist_extensor_collision'>
        <pose frame=''>0 0 -0.02 1.57 -0 0</pose>
        <geometry>
          <cylinder>
            <length>0.04</length>
            <radius>0.03</radius>
          </cylinder>
        </geometry>
        <surface>
          <contact>
            <ode/>
          </contact>
          <friction>
            <ode/>
          </friction>
        </surface>
      </collision>
      <visual name='left_wrist_extensor_visual'>
        <pose frame=''>0 0 -0.02 1.57 -0 0</pose>
        <geometry>
          <cylinder>
            <length>0.04</length>
            <radius>0.03</radius>
          </cylinder>
        </geometry>
        <material>
          <script>
            <uri>__default__</uri>
            <name>__default__</name>
          </script>
        </material>
      </visual>
      <gravity>1</gravity>
      <velocity_decay/>
      <self_collide>0</self_collide>
    </link>
    <joint name='left_wrist_extensor' type='revolute'>
      <child>left_wrist_extensor</child>
      <parent>left_wrist_rotator</parent>
      <axis>
        <xyz>0 1 0</xyz>
        <limit>
          <lower>-1e+16</lower>
          <upper>1e+16</upper>
        </limit>
        <dynamics>
          <damping>0.1</damping>
          <friction>0</friction>
          <spring_reference>0</spring_reference>
          <spring_stiffness>0</spring_stiffness>
        </dynamics>
        <use_parent_model_frame>1</use_parent_model_frame>
      </axis>
      <physics>
        <provide_feedback>1</provide_feedback>
        <ode>
          <provide_feedback>1</provide_feedback>
          <limit>
            <cfm>0</cfm>
            <erp>0.2</erp>
          </limit>
        </ode>
      </physics>
    </joint>
    <link name='left_wrist_adductor'>
      <pose frame=''>0 0.185 0.14 0 -0 0</pose>
      <inertial>
        <pose frame=''>0 0 -0.06 0 -0 0</pose>
        <mass>1</mass>
        <inertia>
          <ixx>0.028125</ixx>
          <ixy>0</ixy>
          <ixz>0</ixz>
          <iyy>0.045</iyy>
          <iyz>0</iyz>
          <izz>0.028125</izz>
        </inertia>
      </inertial>
      <collision name='left_wrist_adductor_collision'>
        <pose frame=''>0 0 -0.06 0 -0 0</pose>
        <geometry>
          <box>
            <size>0.1 0.02 0.12</size>
          </box>
        </geometry>
        <surface>
          <contact>
            <ode/>
          </contact>
          <friction>
            <ode/>
          </friction>
        </surface>
      </collision>
      <visual name='left_wrist_adductor_visual'>
        <pose frame=''>0 0 -0.06 0 -0 0</pose>
        <geometry>
          <box>
            <size>0.1 0.02 0.12</size>
          </box>
        </geometry>
        <material>
          <script>
            <uri>__default__</uri>
            <name>__default__</name>
          </script>
        </material>
      </visual>
      <gravity>1</gravity>
      <velocity_decay/>
      <self_collide>0</self_collide>
    </link>
    <joint name='left_wrist_adductor' type='revolute'>
      <child>left_wrist_adductor</child>
      <parent>left_wrist_extensor</parent>
      <axis>
        <xyz>0 1 0</xyz>
        <limit>
          <lower>-1e+16</lower>
          <upper>1e+16</upper>
        </limit>
        <dynamics>
          <damping>0.1</damping>
          <friction>0</friction>
          <spring_reference>0</spring_reference>
          <spring_stiffness>0</spring_stiffness>
        </dynamics>
        <use_parent_model_frame>1</use_parent_model_frame>
      </axis>
      <physics>
        <provide_feedback>1</provide_feedback>
        <ode>
          <provide_feedback>1</provide_feedback>
          <limit>
            <cfm>0</cfm>
            <erp>0.2</erp>
          </limit>
        </ode>
      </physics>
    </joint>
    <link name='neck_rotator'>
      <pose frame=''>0 0 0.63 0 -0 0</pose>
      <inertial>
        <pose frame=''>0 0 0.01 0 -0 0</pose>
        <mass>0.5</mass>
        <inertia>
          <ixx>0.0028125</ixx>
          <ixy>0</ixy>
          <ixz>0</ixz>
          <iyy>0.0045</iyy>
          <iyz>0</iyz>
          <izz>0.0028125</izz>
        </inertia>
      </inertial>
      <collision name='neck_rotator_collision'>
        <pose frame=''>0 0 0 0 -0 0</pose>
        <geometry>
          <cylinder>
            <length>0.04</length>
            <radius>0.03</radius>
          </cylinder>
        </geometry>
        <surface>
          <contact>
            <ode/>
          </contact>
          <friction>
            <ode/>
          </friction>
        </surface>
      </collision>
      <visual name='neck_rotator_visual'>
        <pose frame=''>0 0 0 0 -0 0</pose>
        <geometry>
          <cylinder>
            <length>0.04</length>
            <radius>0.03</radius>
          </cylinder>
        </geometry>
        <material>
          <script>
            <uri>__default__</uri>
            <name>__default__</name>
          </script>
        </material>
      </visual>
      <gravity>1</gravity>
      <velocity_decay/>
      <self_collide>0</self_collide>
    </link>
    <joint name='neck_rotator' type='revolute'>
      <child>neck_rotator</child>
      <parent>chest</parent>
      <axis>
        <xyz>0 0 1</xyz>
        <limit>
          <lower>-1e+16</lower>
          <upper>1e+16</upper>
        </limit>
        <dynamics>
          <damping>0.1</damping>
          <friction>0</friction>
          <spring_reference>0</spring_reference>
          <spring_stiffness>0</spring_stiffness>
        </dynamics>
        <use_parent_model_frame>1</use_parent_model_frame>
      </axis>
      <physics>
        <provide_feedback>1</provide_feedback>
        <ode>
          <provide_feedback>1</provide_feedback>
          <limit>
            <cfm>0</cfm>
            <erp>0.2</erp>
          </limit>
        </ode>
      </physics>
    </joint>
    <link name='neck_extensor'>
      <pose frame=''>0 0 0.65 0 -0 0</pose>
      <inertial>
        <pose frame=''>0 0 0.01 0 -0 0</pose>
        <mass>0.5</mass>
        <inertia>
          <ixx>0.0028125</ixx>
          <ixy>0</ixy>
          <ixz>0</ixz>
          <iyy>0.0045</iyy>
          <iyz>0</iyz>
          <izz>0.0028125</izz>
        </inertia>
      </inertial>
      <collision name='neck_extensor_collision'>
        <pose frame=''>0 0 0.01 1.57 -0 0</pose>
        <geometry>
          <cylinder>
            <length>0.04</length>
            <radius>0.03</radius>
          </cylinder>
        </geometry>
        <surface>
          <contact>
            <ode/>
          </contact>
          <friction>
            <ode/>
          </friction>
        </surface>
      </collision>
      <visual name='neck_extensor_visual'>
        <pose frame=''>0 0 0.01 1.57 -0 0</pose>
        <geometry>
          <cylinder>
            <length>0.04</length>
            <radius>0.03</radius>
          </cylinder>
        </geometry>
        <material>
          <script>
            <uri>__default__</uri>
            <name>__default__</name>
          </script>
        </material>
      </visual>
      <gravity>1</gravity>
      <velocity_decay/>
      <self_collide>0</self_collide>
    </link>
    <joint name='neck_extensor' type='revolute'>
      <child>neck_extensor</child>
      <parent>neck_rotator</parent>
      <axis>
        <xyz>0 1 0</xyz>
        <limit>
          <lower>-1e+16</lower>
          <upper>1e+16</upper>
        </limit>
        <dynamics>
          <damping>0.1</damping>
          <friction>0</friction>
          <spring_reference>0</spring_reference>
          <spring_stiffness>0</spring_stiffness>
        </dynamics>
        <use_parent_model_frame>1</use_parent_model_frame>
      </axis>
      <physics>
        <provide_feedback>1</provide_feedback>
        <ode>
          <provide_feedback>1</provide_feedback>
          <limit>
            <cfm>0</cfm>
            <erp>0.2</erp>
          </limit>
        </ode>
      </physics>
    </joint>
    <link name='neck_adductor'>
      <pose frame=''>0 0 0.67 0 -0 0</pose>
      <inertial>
        <pose frame=''>0 0 0.106 0 -0 0</pose>
        <mass>2.5</mass>
        <inertia>
          <ixx>0.011385</ixx>
          <ixy>0</ixy>
          <ixz>0</ixz>
          <iyy>0.01476</iyy>
          <iyz>0</iyz>
          <izz>0.005625</izz>
        </inertia>
      </inertial>
      <collision name='neck_adductor_collision'>
        <pose frame=''>0 0 0.01 0 1.57 0</pose>
        <geometry>
          <cylinder>
            <length>0.04</length>
            <radius>0.03</radius>
          </cylinder>
        </geometry>
        <surface>
          <contact>
            <ode/>
          </contact>
          <friction>
            <ode/>
          </friction>
        </surface>
      </collision>
      <collision name='neck_adductor_lump::head_collision_1'>
        <pose frame=''>0 0 0.13 0 1.57 0</pose>
        <geometry>
          <sphere>
            <radius>0.1</radius>
          </sphere>
        </geometry>
      </collision>
      <visual name='neck_adductor_visual'>
        <pose frame=''>0 0 0.01 0 1.57 0</pose>
        <geometry>
          <cylinder>
            <length>0.04</length>
            <radius>0.03</radius>
          </cylinder>
        </geometry>
        <material>
          <script>
            <uri>__default__</uri>
            <name>__default__</name>
          </script>
        </material>
      </visual>
      <visual name='neck_adductor_lump::head_visual_1'>
        <pose frame=''>0 0 0.13 0 1.57 0</pose>
        <geometry>
          <sphere>
            <radius>0.1</radius>
          </sphere>
        </geometry>
      </visual>
      <gravity>1</gravity>
      <velocity_decay/>
      <self_collide>0</self_collide>
    </link>
    <joint name='neck_adductor' type='revolute'>
      <child>neck_adductor</child>
      <parent>neck_extensor</parent>
      <axis>
        <xyz>1 0 0</xyz>
        <limit>
          <lower>-1e+16</lower>
          <upper>1e+16</upper>
        </limit>
        <dynamics>
          <damping>0.1</damping>
          <friction>0</friction>
          <spring_reference>0</spring_reference>
          <spring_stiffness>0</spring_stiffness>
        </dynamics>
        <use_parent_model_frame>1</use_parent_model_frame>
      </axis>
      <physics>
        <provide_feedback>1</provide_feedback>
        <ode>
          <provide_feedback>1</provide_feedback>
          <limit>
            <cfm>0</cfm>
            <erp>0.2</erp>
          </limit>
        </ode>
      </physics>
    </joint>
    <link name='right_shoulder_extensor'>
      <pose frame=''>0 -0.125 0.6 0 -0 0</pose>
      <inertial>
        <pose frame=''>0 -0.01 0 0 -0 0</pose>
        <mass>1</mass>
        <inertia>
          <ixx>0.028125</ixx>
          <ixy>0</ixy>
          <ixz>0</ixz>
          <iyy>0.045</iyy>
          <iyz>0</iyz>
          <izz>0.028125</izz>
        </inertia>
      </inertial>
      <collision name='right_shoulder_extensor_collision'>
        <pose frame=''>0 -0.01 0 1.57 -0 0</pose>
        <geometry>
          <cylinder>
            <length>0.02</length>
            <radius>0.06</radius>
          </cylinder>
        </geometry>
        <surface>
          <contact>
            <ode/>
          </contact>
          <friction>
            <ode/>
          </friction>
        </surface>
      </collision>
      <visual name='right_shoulder_extensor_visual'>
        <pose frame=''>0 -0.01 0 1.57 -0 0</pose>
        <geometry>
          <cylinder>
            <length>0.02</length>
            <radius>0.06</radius>
          </cylinder>
        </geometry>
        <material>
          <script>
            <uri>__default__</uri>
            <name>__default__</name>
          </script>
        </material>
      </visual>
      <gravity>1</gravity>
      <velocity_decay/>
      <self_collide>0</self_collide>
    </link>
    <joint name='right_shoulder_extensor' type='revolute'>
      <child>right_shoulder_extensor</child>
      <parent>chest</parent>
      <axis>
        <xyz>0 1 0</xyz>
        <limit>
          <lower>-1e+16</lower>
          <upper>1e+16</upper>
        </limit>
        <dynamics>
          <damping>0.1</damping>
          <friction>0</friction>
          <spring_reference>0</spring_reference>
          <spring_stiffness>0</spring_stiffness>
        </dynamics>
        <use_parent_model_frame>1</use_parent_model_frame>
      </axis>
      <physics>
        <provide_feedback>1</provide_feedback>
        <ode>
          <provide_feedback>1</provide_feedback>
          <limit>
            <cfm>0</cfm>
            <erp>0.2</erp>
          </limit>
        </ode>
      </physics>
    </joint>
    <link name='right_shoulder_adductor'>
      <pose frame=''>0 -0.165 0.6 0 -0 0</pose>
      <inertial>
        <pose frame=''>0 -0.02 0 0 -0 0</pose>
        <mass>1</mass>
        <inertia>
          <ixx>0.028125</ixx>
          <ixy>0</ixy>
          <ixz>0</ixz>
          <iyy>0.045</iyy>
          <iyz>0</iyz>
          <izz>0.028125</izz>
        </inertia>
      </inertial>
      <collision name='right_shoulder_adductor_collision'>
        <pose frame=''>0 -0.02 0 0 1.57 0</pose>
        <geometry>
          <cylinder>
            <length>0.1</length>
            <radius>0.04</radius>
          </cylinder>
        </geometry>
        <surface>
          <contact>
            <ode/>
          </contact>
          <friction>
            <ode/>
          </friction>
        </surface>
      </collision>
      <visual name='right_shoulder_adductor_visual'>
        <pose frame=''>0 -0.02 0 0 1.57 0</pose>
        <geometry>
          <cylinder>
            <length>0.1</length>
            <radius>0.04</radius>
          </cylinder>
        </geometry>
        <material>
          <script>
            <uri>__default__</uri>
            <name>__default__</name>
          </script>
        </material>
      </visual>
      <gravity>1</gravity>
      <velocity_decay/>
      <self_collide>0</self_collide>
    </link>
    <joint name='right_shoulder_adductor' type='revolute'>
      <child>right_shoulder_adductor</child>
      <parent>right_shoulder_extensor</parent>
      <axis>
        <xyz>1 0 0</xyz>
        <limit>
          <lower>-1e+16</lower>
          <upper>1e+16</upper>
        </limit>
        <dynamics>
          <damping>0.1</damping>
          <friction>0</friction>
          <spring_reference>0</spring_reference>
          <spring_stiffness>0</spring_stiffness>
        </dynamics>
        <use_parent_model_frame>1</use_parent_model_frame>
      </axis>
      <physics>
        <provide_feedback>1</provide_feedback>
        <ode>
          <provide_feedback>1</provide_feedback>
          <limit>
            <cfm>0</cfm>
            <erp>0.2</erp>
          </limit>
        </ode>
      </physics>
    </joint>
    <link name='right_shoulder_rotator'>
      <pose frame=''>0 -0.185 0.58 0 -0 0</pose>
      <inertial>
        <pose frame=''>0 0 -0.1 0 -0 0</pose>
        <mass>2</mass>
        <inertia>
          <ixx>0.028125</ixx>
          <ixy>0</ixy>
          <ixz>0</ixz>
          <iyy>0.045</iyy>
          <iyz>0</iyz>
          <izz>0.028125</izz>
        </inertia>
      </inertial>
      <collision name='right_shoulder_rotator_collision'>
        <pose frame=''>0 0 -0.1 0 -0 0</pose>
        <geometry>
          <cylinder>
            <length>0.2</length>
            <radius>0.03</radius>
          </cylinder>
        </geometry>
        <surface>
          <contact>
            <ode/>
          </contact>
          <friction>
            <ode/>
          </friction>
        </surface>
      </collision>
      <visual name='right_shoulder_rotator_visual'>
        <pose frame=''>0 0 -0.1 0 -0 0</pose>
        <geometry>
          <cylinder>
            <length>0.2</length>
            <radius>0.03</radius>
          </cylinder>
        </geometry>
        <material>
          <script>
            <uri>__default__</uri>
            <name>__default__</name>
          </script>
        </material>
      </visual>
      <gravity>1</gravity>
      <velocity_decay/>
      <self_collide>0</self_collide>
    </link>
    <joint name='right_shoulder_rotator' type='revolute'>
      <child>right_shoulder_rotator</child>
      <parent>right_shoulder_adductor</parent>
      <axis>
        <xyz>0 0 1</xyz>
        <limit>
          <lower>-1e+16</lower>
          <upper>1e+16</upper>
        </limit>
        <dynamics>
          <damping>0.1</damping>
          <friction>0</friction>
          <spring_reference>0</spring_reference>
          <spring_stiffness>0</spring_stiffness>
        </dynamics>
        <use_parent_model_frame>1</use_parent_model_frame>
      </axis>
      <physics>
        <provide_feedback>1</provide_feedback>
        <ode>
          <provide_feedback>1</provide_feedback>
          <limit>
            <cfm>0</cfm>
            <erp>0.2</erp>
          </limit>
        </ode>
      </physics>
    </joint>
    <link name='right_elbow_extensor'>
      <pose frame=''>0 -0.185 0.38 0 -0 0</pose>
      <inertial>
        <pose frame=''>0 0 -0.1 0 -0 0</pose>
        <mass>2</mass>
        <inertia>
          <ixx>0.028125</ixx>
          <ixy>0</ixy>
          <ixz>0</ixz>
          <iyy>0.045</iyy>
          <iyz>0</iyz>
          <izz>0.028125</izz>
        </inertia>
      </inertial>
      <collision name='right_elbow_extensor_collision'>
        <pose frame=''>0 0 -0.1 0 -0 0</pose>
        <geometry>
          <cylinder>
            <length>0.2</length>
            <radius>0.03</radius>
          </cylinder>
        </geometry>
        <surface>
          <contact>
            <ode/>
          </contact>
          <friction>
            <ode/>
          </friction>
        </surface>
      </collision>
      <visual name='right_elbow_extensor_visual'>
        <pose frame=''>0 0 -0.1 0 -0 0</pose>
        <geometry>
          <cylinder>
            <length>0.2</length>
            <radius>0.03</radius>
          </cylinder>
        </geometry>
        <material>
          <script>
            <uri>__default__</uri>
            <name>__default__</name>
          </script>
        </material>
      </visual>
      <gravity>1</gravity>
      <velocity_decay/>
      <self_collide>0</self_collide>
    </link>
    <joint name='right_elbow_extensor' type='revolute'>
      <child>right_elbow_extensor</child>
      <parent>right_shoulder_rotator</parent>
      <axis>
        <xyz>0 1 0</xyz>
        <limit>
          <lower>-1e+16</lower>
          <upper>1e+16</upper>
        </limit>
        <dynamics>
          <damping>0.1</damping>
          <friction>0</friction>
          <spring_reference>0</spring_reference>
          <spring_stiffness>0</spring_stiffness>
        </dynamics>
        <use_parent_model_frame>1</use_parent_model_frame>
      </axis>
      <physics>
        <provide_feedback>1</provide_feedback>
        <ode>
          <provide_feedback>1</provide_feedback>
          <limit>
            <cfm>0</cfm>
            <erp>0.2</erp>
          </limit>
        </ode>
      </physics>
    </joint>
    <link name='right_wrist_rotator'>
      <pose frame=''>0 -0.185 0.18 0 -0 0</pose>
      <inertial>
        <pose frame=''>0 0 -0.02 0 -0 0</pose>
        <mass>2</mass>
        <inertia>
          <ixx>0.028125</ixx>
          <ixy>0</ixy>
          <ixz>0</ixz>
          <iyy>0.045</iyy>
          <iyz>0</iyz>
          <izz>0.028125</izz>
        </inertia>
      </inertial>
      <collision name='right_wrist_rotator_collision'>
        <pose frame=''>0 0 -0.02 0 -0 0</pose>
        <geometry>
          <cylinder>
            <length>0.04</length>
            <radius>0.03</radius>
          </cylinder>
        </geometry>
        <surface>
          <contact>
            <ode/>
          </contact>
          <friction>
            <ode/>
          </friction>
        </surface>
      </collision>
      <visual name='right_wrist_rotator_visual'>
        <pose frame=''>0 0 -0.02 0 -0 0</pose>
        <geometry>
          <cylinder>
            <length>0.04</length>
            <radius>0.03</radius>
          </cylinder>
        </geometry>
        <material>
          <script>
            <uri>__default__</uri>
            <name>__default__</name>
          </script>
        </material>
      </visual>
      <gravity>1</gravity>
      <velocity_decay/>
      <self_collide>0</self_collide>
    </link>
    <joint name='right_wrist_rotator' type='revolute'>
      <child>right_wrist_rotator</child>
      <parent>right_elbow_extensor</parent>
      <axis>
        <xyz>0 0 1</xyz>
        <limit>
          <lower>-1e+16</lower>
          <upper>1e+16</upper>
        </limit>
        <dynamics>
          <damping>0.1</damping>
          <friction>0</friction>
          <spring_reference>0</spring_reference>
          <spring_stiffness>0</spring_stiffness>
        </dynamics>
        <use_parent_model_frame>1</use_parent_model_frame>
      </axis>
      <physics>
        <provide_feedback>1</provide_feedback>
        <ode>
          <provide_feedback>1</provide_feedback>
          <limit>
            <cfm>0</cfm>
            <erp>0.2</erp>
          </limit>
        </ode>
      </physics>
    </joint>
    <link name='right_wrist_extensor'>
      <pose frame=''>0 -0.185 0.16 0 -0 0</pose>
      <inertial>
        <pose frame=''>0 0 -0.02 0 -0 0</pose>
        <mass>1</mass>
        <inertia>
          <ixx>0.028125</ixx>
          <ixy>0</ixy>
          <ixz>0</ixz>
          <iyy>0.045</iyy>
          <iyz>0</iyz>
          <izz>0.028125</izz>
        </inertia>
      </inertial>
      <collision name='right_wrist_extensor_collision'>
        <pose frame=''>0 0 -0.02 1.57 -0 0</pose>
        <geometry>
          <cylinder>
            <length>0.04</length>
            <radius>0.03</radius>
          </cylinder>
        </geometry>
        <surface>
          <contact>
            <ode/>
          </contact>
          <friction>
            <ode/>
          </friction>
        </surface>
      </collision>
      <visual name='right_wrist_extensor_visual'>
        <pose frame=''>0 0 -0.02 1.57 -0 0</pose>
        <geometry>
          <cylinder>
            <length>0.04</length>
            <radius>0.03</radius>
          </cylinder>
        </geometry>
        <material>
          <script>
            <uri>__default__</uri>
            <name>__default__</name>
          </script>
        </material>
      </visual>
      <gravity>1</gravity>
      <velocity_decay/>
      <self_collide>0</self_collide>
    </link>
    <joint name='right_wrist_extensor' type='revolute'>
      <child>right_wrist_extensor</child>
      <parent>right_wrist_rotator</parent>
      <axis>
        <xyz>0 1 0</xyz>
        <limit>
          <lower>-1e+16</lower>
          <upper>1e+16</upper>
        </limit>
        <dynamics>
          <damping>0.1</damping>
          <friction>0</friction>
          <spring_reference>0</spring_reference>
          <spring_stiffness>0</spring_stiffness>
        </dynamics>
        <use_parent_model_frame>1</use_parent_model_frame>
      </axis>
      <physics>
        <provide_feedback>1</provide_feedback>
        <ode>
          <provide_feedback>1</provide_feedback>
          <limit>
            <cfm>0</cfm>
            <erp>0.2</erp>
          </limit>
        </ode>
      </physics>
    </joint>
    <link name='right_wrist_adductor'>
      <pose frame=''>0 -0.185 0.14 0 -0 0</pose>
      <inertial>
        <pose frame=''>0 0 -0.06 0 -0 0</pose>
        <mass>1</mass>
        <inertia>
          <ixx>0.028125</ixx>
          <ixy>0</ixy>
          <ixz>0</ixz>
          <iyy>0.045</iyy>
          <iyz>0</iyz>
          <izz>0.028125</izz>
        </inertia>
      </inertial>
      <collision name='right_wrist_adductor_collision'>
        <pose frame=''>0 0 -0.06 0 -0 0</pose>
        <geometry>
          <box>
            <size>0.1 0.02 0.12</size>
          </box>
        </geometry>
        <surface>
          <contact>
            <ode/>
          </contact>
          <friction>
            <ode/>
          </friction>
        </surface>
      </collision>
      <visual name='right_wrist_adductor_visual'>
        <pose frame=''>0 0 -0.06 0 -0 0</pose>
        <geometry>
          <box>
            <size>0.1 0.02 0.12</size>
          </box>
        </geometry>
        <material>
          <script>
            <uri>__default__</uri>
            <name>__default__</name>
          </script>
        </material>
      </visual>
      <gravity>1</gravity>
      <velocity_decay/>
      <self_collide>0</self_collide>
    </link>
    <joint name='right_wrist_adductor' type='revolute'>
      <child>right_wrist_adductor</child>
      <parent>right_wrist_extensor</parent>
      <axis>
        <xyz>0 1 0</xyz>
        <limit>
          <lower>-1e+16</lower>
          <upper>1e+16</upper>
        </limit>
        <dynamics>
          <damping>0.1</damping>
          <friction>0</friction>
          <spring_reference>0</spring_reference>
          <spring_stiffness>0</spring_stiffness>
        </dynamics>
        <use_parent_model_frame>1</use_parent_model_frame>
      </axis>
      <physics>
        <provide_feedback>1</provide_feedback>
        <ode>
          <provide_feedback>1</provide_feedback>
          <limit>
            <cfm>0</cfm>
            <erp>0.2</erp>
          </limit>
        </ode>
      </physics>
    </joint>
  </model>
</sdf>
