<sdf version='1.5'>
  <model name='stickbot_lowerleg_3dof'>
    <link name='foot'>
      <pose frame=''>0 0 0 0 -0 0</pose>
      <inertial>
        <pose frame=''>0 0 0 0 -0 0</pose>
        <mass>10</mass>
        <inertia>
          <ixx>0.008667</ixx>
          <ixy>0</ixy>
          <ixz>0</ixz>
          <iyy>0.008667</iyy>
          <iyz>0</iyz>
          <izz>0.01667</izz>
        </inertia>
      </inertial>
      <collision name='foot_collision'>
        <pose frame=''>0 0 0.02 0 -0 0</pose>
        <geometry>
          <box>
            <size>0.5 0.3 0.04</size>
          </box>
        </geometry>
      </collision>
      <visual name='foot_visual'>
        <pose frame=''>0 0 0.01 0 -0 0</pose>
        <geometry>
          <box>
            <size>0.5 0.3 0.04</size>
          </box>
        </geometry>
      </visual>
    </link>
    <link name='ankleLink'>
      <pose frame=''>-0.025 0 0.015 0 -0 0</pose>
      <inertial>
        <pose frame=''>0 0 0.015 0 -0 0</pose>
        <mass>0.25</mass>
        <inertia>
          <ixx>0.00015</ixx>
          <ixy>0</ixy>
          <ixz>0</ixz>
          <iyy>0.00015</iyy>
          <iyz>0</iyz>
          <izz>0.000225</izz>
        </inertia>
      </inertial>
      <collision name='ankleLink_collision'>
        <pose frame=''>0 0 0.015 1.507 -0 0</pose>
        <geometry>
          <cylinder>
            <length>0.03</length>
            <radius>0.03</radius>
          </cylinder>
        </geometry>
      </collision>
      <visual name='ankleLink_visual'>
        <pose frame=''>0 0 0.015 1.507 -0 0</pose>
        <geometry>
          <cylinder>
            <length>0.03</length>
            <radius>0.03</radius>
          </cylinder>
        </geometry>
      </visual>
    </link>
    <joint name='ankleRoll' type='revolute'>
      <child>ankleLink</child>
      <parent>foot</parent>
      <axis>
        <xyz>1 0 0</xyz>
        <limit>
          <lower>-1e+16</lower>
          <upper>1e+16</upper>
        </limit>
        <dynamics>
          <damping>0</damping>
          <friction>0</friction>
          <spring_reference>0</spring_reference>
          <spring_stiffness>0</spring_stiffness>
        </dynamics>
        <use_parent_model_frame>1</use_parent_model_frame>
      </axis>
      <physics>
        <provide_feedback>1</provide_feedback>
        <ode>
          <provide_feedback>1</provide_feedback>
          <limit>
            <cfm>0</cfm>
            <erp>0.2</erp>
          </limit>
        </ode>
      </physics>
    </joint>
    <link name='lowerLeg'>
      <pose frame=''>-0.025 0 0.045 0 -0 0</pose>
      <inertial>
        <pose frame=''>-0 0 0.15 0 -0 0</pose>
        <mass>2</mass>
        <inertia>
          <ixx>0.01545</ixx>
          <ixy>0</ixy>
          <ixz>0</ixz>
          <iyy>0.01545</iyy>
          <iyz>0</iyz>
          <izz>0.0009</izz>
        </inertia>
      </inertial>
      <collision name='lowerLeg_collision'>
        <pose frame=''>0 0 0.15 0 -0 0</pose>
        <geometry>
          <cylinder>
            <length>0.3</length>
            <radius>0.03</radius>
          </cylinder>
        </geometry>
      </collision>
      <visual name='lowerLeg_visual'>
        <pose frame=''>0 0 0.15 0 -0 0</pose>
        <geometry>
          <cylinder>
            <length>0.3</length>
            <radius>0.03</radius>
          </cylinder>
        </geometry>
      </visual>
    </link>
    <joint name='anklePitch' type='revolute'>
      <child>lowerLeg</child>
      <parent>ankleLink</parent>
      <axis>
        <xyz>0 1 0</xyz>
        <limit>
          <lower>-1e+16</lower>
          <upper>1e+16</upper>
        </limit>
        <dynamics>
          <spring_reference>0</spring_reference>
          <spring_stiffness>0</spring_stiffness>
        </dynamics>
        <use_parent_model_frame>1</use_parent_model_frame>
      </axis>
      <physics>
        <provide_feedback>1</provide_feedback>
        <ode>
          <provide_feedback>1</provide_feedback>
          <limit>
            <cfm>0</cfm>
            <erp>0.2</erp>
          </limit>
        </ode>
      </physics>
    </joint>
    <link name='upperleg'>
      <pose frame=''>-0.025 0 0.345 0 -0 0</pose>
      <inertial>
        <pose frame=''>-0 0 0.15 0 -0 0</pose>
        <mass>2</mass>
        <inertia>
          <ixx>0.01545</ixx>
          <ixy>0</ixy>
          <ixz>0</ixz>
          <iyy>0.01545</iyy>
          <iyz>0</iyz>
          <izz>0.0009</izz>
        </inertia>
      </inertial>
      <collision name='upperleg_collision'>
        <pose frame=''>0 0 0.3 0 -0 0</pose>
        <geometry>
          <cylinder>
            <length>0.3</length>
            <radius>0.03</radius>
          </cylinder>
        </geometry>
      </collision>
      <visual name='upperleg_visual'>
        <pose frame=''>0 0 0.15 0 -0 0</pose>
        <geometry>
          <cylinder>
            <length>0.3</length>
            <radius>0.03</radius>
          </cylinder>
        </geometry>
      </visual>
    </link>
    <joint name='knee' type='revolute'>
      <child>upperleg</child>
      <parent>lowerLeg</parent>
      <axis>
        <xyz>0 1 0</xyz>
        <limit>
          <lower>-1e+16</lower>
          <upper>1e+16</upper>
        </limit>
        <dynamics>
          <spring_reference>0</spring_reference>
          <spring_stiffness>0</spring_stiffness>
        </dynamics>
        <use_parent_model_frame>1</use_parent_model_frame>
      </axis>
      <physics>
        <provide_feedback>1</provide_feedback>
        <ode>
          <provide_feedback>1</provide_feedback>
          <limit>
            <cfm>0</cfm>
            <erp>0.2</erp>
          </limit>
        </ode>
      </physics>
    </joint>
  </model>
</sdf>
