<?xml version="1.0" ?>
<!-- =================================================================================== -->
<!-- |    This document was autogenerated by xacro from xacro/stickbot_lowerleg_3dof.xacro | -->
<!-- |    EDITING THIS FILE BY HAND IS NOT RECOMMENDED                                 | -->
<!-- =================================================================================== -->
<robot name="stickbot_lowerleg_3dof" xmlns:controller="http://playerstage.sourceforge.net/gazebo/xmlschema/#controller" xmlns:interface="http://playerstage.sourceforge.net/gazebo/xmlschema/#interface" xmlns:sensor="http://playerstage.sourceforge.net/gazebo/xmlschema/#sensor" xmlns:xacro="http://playerstage.sourceforge.net/gazebo/xmlschema/#interface">
  <!-- Add the foot -->
  <link name="foot">
    <inertial>
      <mass value="10"/>
      <origin xyz="0 0 0.0"/>
      <inertia ixx="0.008667" ixy="0" ixz="0" iyy="0.008667" iyz="0" izz="0.01667"/>
      <!-- <inertia ixx="0.01667" ixy="0" ixz="0" iyy="0.01667" iyz="0" izz="0.00866"/> -->
    </inertial>
    <visual>
      <origin rpy="0 0 0 " xyz="0 0 0.01"/>
      <geometry name="foot">
        <box size="0.5 0.3 0.04"/>
        <!-- NOTE: These dimensions don't match inertial dimensions -->
      </geometry>
      <material name="grey">
        <color rgba="0.627 0.627 0.627 1"/>
      </material>
    </visual>
    <collision>
      <origin rpy="0 0 0 " xyz="0 0 0.02"/>
      <geometry name="foot">
        <box size="0.5 0.3 0.04"/>
      </geometry>
    </collision>
  </link>
  <!-- ankleRoll enables the ankle to roll -->
  <joint name="ankleRoll" type="continuous">
    <axis xyz="1 0 0"/>
    <origin rpy="0.0 0 0" xyz="-0.025 0 0.015"/>
    <parent link="foot"/>
    <child link="ankleLink"/>
    <limit effort="100" lower="-3.14" upper="3.14" velocity="1"/>
    <dynamics damping="0" friction="0"/>
  </joint>
  <!-- ankleLink is the small link that directly attaches to the foot -->
  <link name="ankleLink">
    <inertial>
      <mass value="0.25"/>
      <origin xyz="0.0 0.0 0.015"/>
      <inertia ixx="0.00015" ixy="0" ixz="0" iyy="0.00015" iyz="0" izz="0.000225"/>
    </inertial>
    <visual>
      <origin rpy="1.507 0 0" xyz="0 0 0.015"/>
      <geometry name="ankleLink">
        <cylinder length="0.03" radius="0.03"/>
      </geometry>
      <material name="grey">
        <color rgba="0.627 0.627 0.627 1"/>
      </material>
    </visual>
    <collision>
      <origin rpy="1.507 0 0.0 " xyz="0 0 0.015"/>
      <geometry name="ankleLink">
        <cylinder length="0.03" radius="0.03"/>
      </geometry>
    </collision>
  </link>
  <joint name="anklePitch" type="continuous">
    <axis xyz="0 1 0"/>
    <origin rpy="0 0 0" xyz="0 0 0.03"/>
    <parent link="ankleLink"/>
    <child link="lowerLeg"/>
    <limit effort="100" lower="-3.14" upper="3.14" velocity="1"/>
  </joint>
  <link name="lowerLeg">
    <inertial>
      <mass value="2.0"/>
      <origin xyz="-0.0 0 0.15"/>
      <inertia ixx="0.01545" ixy="0" ixz="0" iyy="0.01545" iyz="0" izz="0.0009"/>
    </inertial>
    <visual>
      <origin rpy="0 0 0 " xyz="0 0 0.15"/>
      <geometry name="lowerLeg">
        <cylinder length="0.3" radius="0.03"/>
      </geometry>
      <material name="grey">
        <color rgba="0.627 0.627 0.627 1"/>
      </material>
    </visual>
    <collision>
      <origin rpy="0 0 0 " xyz="0 0 0.15"/>
      <geometry name="lowerLeg">
        <cylinder length="0.3" radius="0.03"/>
      </geometry>
    </collision>
  </link>
  <joint name="knee" type="continuous">
    <axis xyz="0 1 0"/>
    <origin rpy="0 0 0" xyz="0 0 0.3"/>
    <parent link="lowerLeg"/>
    <child link="upperleg"/>
    <limit effort="100" lower="-3.14" upper="3.14" velocity="1"/>
  </joint>
  <link name="upperleg">
    <inertial>
      <mass value="2.0"/>
      <origin xyz="-0.0 0 0.15"/>
      <inertia ixx="0.01545" ixy="0" ixz="0" iyy="0.01545" iyz="0" izz="0.0009"/>
    </inertial>
    <visual>
      <origin rpy="0 0 0 " xyz="0 0 0.15"/>
      <geometry name="upperleg">
        <cylinder length="0.3" radius="0.03"/>
      </geometry>
      <material name="grey">
        <color rgba="0.627 0.627 0.627 1"/>
      </material>
    </visual>
    <collision>
      <origin rpy="0 0 0 " xyz="0 0 0.3"/>
      <geometry name="upperleg">
        <cylinder length="0.3" radius="0.03"/>
      </geometry>
    </collision>
  </link>
  <gazebo reference="ankleRoll">
    <provideFeedback value="true"/>
  </gazebo>
  <gazebo reference="anklePitch">
    <provideFeedback value="true"/>
  </gazebo>
  <gazebo reference="knee">
    <provideFeedback value="true"/>
  </gazebo>
</robot>
