<?xml version="1.0"?>

<robot xmlns="http://drake.mit.edu"
  xmlns:xsi="http://www.w3.org/2001/XMLSchema-instance"
  xsi:schemaLocation="http://drake.mit.edu ../../doc/drakeURDF.xsd" name="Acrobot">

  <link name="base_link">
    <!--
    The following inertial tag was added by Liang to enable this URDF
    to be converted into SDF and loaded into Gazebo. The inertia tensor
    was obtained from:

    https://en.wikipedia.org/wiki/List_of_moments_of_inertia
    -->
    <inertial>
      <mass value="1"/>
      <origin rpy="0 0 0" xyz="0 0 0"/>
      <inertia ixx="0.006666667" ixy="0.0" ixz="0.0" iyy="0.006666667" iyz="0.0" izz="0.006666667"/>
    </inertial>

    <visual>
      <geometry>
         <box size=".2 .2 .2" />
      </geometry>
      <material name="green">
        <color rgba="0 1 0 1" />
      </material>
    </visual>

    <!--
    The following collision tag was added by Liang to prevent the robot from sinking through the floor in Gazebo.
    -->
    <collision>
      <origin rpy="0 0 0 " xyz="0 0 0"/>
      <geometry name="box">
        <box size="0.2 0.2 0.2"/>
      </geometry>
    </collision>

  </link>

  <link name="upper_link">
    <inertial>
      <origin xyz="0 0 -.5" rpy="0 0 0" />
      <mass value="1" />
      <inertia ixx="1" ixy="0" ixz="0" iyy="0.083" iyz="0" izz="1" />
    </inertial>
    <visual>
      <origin xyz="0 0 -.5" rpy="0 0 0" />
      <geometry>
        <cylinder length="1.1" radius=".05" />
      </geometry>
      <material name="red">
        <color rgba="1 0 0 1" />
      </material>
    </visual>

    <!--
    The following collision tag was added by Liang for Gazebo compatibility.
    -->
    <collision>
      <origin rpy="0 0 0 " xyz="0 0 -0.5"/>
      <geometry name="cylinder">
        <cylinder length="1.1" radius=".05" />
      </geometry>
    </collision>
  </link>

  <link name="lower_link">
    <inertial>
      <origin xyz="0 0 -1" rpy="0 0 0" />
      <mass value="1" />
      <inertia ixx="1" ixy="0" ixz="0" iyy="0.33" iyz="0" izz="1" />
    </inertial>
    <visual>
      <origin xyz="0 0 -1" rpy="0 0 0" />
      <geometry>
         <cylinder length="2.1" radius=".05" />
      </geometry>
      <material name="blue">
        <color rgba="0 0 1 1" />
      </material>
    </visual>

    <!--
    The following collision tag was added by Liang for Gazebo compatibility.
    -->
    <collision>
      <origin rpy="0 0 0 " xyz="0 0 -1"/>
      <geometry name="cylinder">
        <cylinder length="2.1" radius=".05" />
      </geometry>
    </collision>
  </link>

  <joint name="shoulder" type="continuous">
    <parent link="base_link" />
    <child link="upper_link" />
    <origin xyz="0 .15 0" />
    <axis xyz="0 1 0" />
    <dynamics damping="0.1" />
  </joint>

  <joint name="elbow" type="continuous">
    <parent link="upper_link" />
    <child link="lower_link" />
    <origin xyz="0 .1 -1" />
    <axis xyz="0 1 0" />
    <dynamics damping="0.1" />
  </joint>

  <transmission type="SimpleTransmission" name="elbow_trans">
    <actuator name="elbow_torque" />
    <joint name="elbow" />
    <mechanicalReduction>1</mechanicalReduction>
  </transmission>

  <frame name="hand" link="lower_link" xyz="0 0 -2.1" rpy="0 0 0" />
</robot>
